<mujoco model="allegro_hand_right">
    <compiler angle="radian" />
    <size njmax="500" nconmax="100" />
    <asset>
        <mesh name="base_link" file="base_link.STL" />
        <mesh name="link_0.0" file="link_0.0.STL" />
        <mesh name="link_1.0" file="link_1.0.STL" />
        <mesh name="link_2.0" file="link_2.0.STL" />
        <mesh name="link_3.0" file="link_3.0.STL" />
        <mesh name="fingertip_V2_fixed2" file="fingertip_V2_fixed2.STL" scale="0.001 0.001 0.001" />
        <mesh name="link_12.0_right" file="link_12.0_right.STL" />
        <mesh name="link_13.0" file="link_13.0.STL" />
        <mesh name="link_14.0" file="link_14.0.STL" />
        <mesh name="link_15.0" file="link_15.0.STL" />
    </asset>
    <worldbody>
        <geom type="mesh" mesh="base_link" />
        <body name="link_0" pos="0 0.0435 -0.001542" quat="0.999048 -0.0436194 0 0">
            <inertial pos="-0.000778127 -1.02867e-05 0.00828249" quat="0.684133 0.685936 -0.175375 0.175209" mass="0.00868607" diaginertia="9.19262e-07 8.2734e-07 4.2643e-07" />
            <joint name="joint_0" pos="0 0 0" axis="0 0 1" limited="true" range="-0.47 0.47" damping="3" frictionloss="10" />
            <geom type="mesh" mesh="link_0.0" />
            <body name="link_1" pos="0 0 0.0164">
                <inertial pos="2.75253e-08 -9.05957e-05 0.0269998" quat="1 -3.06263e-06 1.74064e-11 5.68349e-06" mass="0.0326268" diaginertia="1.41894e-05 1.3489e-05 2.71036e-06" />
                <joint name="joint_1" pos="0 0 0" axis="0 1 0" limited="true" range="-0.196 1.61" damping="3" frictionloss="5" />
                <geom type="mesh" mesh="link_1.0" />
                <body name="link_2" pos="0 0 0.054">
                    <inertial pos="-0.000192882 -7.79043e-05 0.022586" quat="0.999903 -0.000286998 0.0139235 0.000170086" mass="0.0225751" diaginertia="5.24199e-06 4.4452e-06 2.04635e-06" />
                    <joint name="joint_2" pos="0 0 0" axis="0 1 0" limited="true" range="-0.174 1.709" damping="8" frictionloss="10" />
                    <geom type="mesh" mesh="link_2.0" />
                    <body name="link_3" pos="0 0 0.0384">
                        <inertial pos="0.00363545 -1.70642e-06 0.0107468" quat="0.961434 -8.14196e-05 0.275036 7.26886e-05" mass="0.0174601" diaginertia="2.33005e-06 1.88686e-06 1.3466e-06" />
                        <joint name="joint_3" pos="0 0 0" axis="0 1 0" limited="true" range="-0.227 1.618" damping="10" frictionloss="12" />
                        <geom type="mesh" mesh="link_3.0" />
                        <geom pos="0.002 0 0.0007" type="mesh" mesh="fingertip_V2_fixed2" />
                    </body>
                </body>
            </body>
        </body>
        <body name="link_4" pos="0 0 0.0007">
            <inertial pos="-0.000778127 -1.02867e-05 0.00828249" quat="0.684133 0.685936 -0.175375 0.175209" mass="0.00868607" diaginertia="9.19262e-07 8.2734e-07 4.2643e-07" />
            <joint name="joint_4" pos="0 0 0" axis="0 0 1" limited="true" range="-0.47 0.47" damping="3" frictionloss="10" />
            <geom type="mesh" mesh="link_0.0" />
            <body name="link_5" pos="0 0 0.0164">
                <inertial pos="2.75253e-08 -9.05957e-05 0.0269998" quat="1 -3.06263e-06 1.74064e-11 5.68349e-06" mass="0.0326268" diaginertia="1.41894e-05 1.3489e-05 2.71036e-06" />
                <joint name="joint_5" pos="0 0 0" axis="0 1 0" limited="true" range="-0.196 1.61" damping="3" frictionloss="5" />
                <geom type="mesh" mesh="link_1.0" />
                <body name="link_6" pos="0 0 0.054">
                    <inertial pos="-0.000192882 -7.79043e-05 0.022586" quat="0.999903 -0.000286998 0.0139235 0.000170086" mass="0.0225751" diaginertia="5.24199e-06 4.4452e-06 2.04635e-06" />
                    <joint name="joint_6" pos="0 0 0" axis="0 1 0" limited="true" range="-0.174 1.709" damping="8" frictionloss="10" />
                    <geom type="mesh" mesh="link_2.0" />
                    <body name="link_7" pos="0 0 0.0384">
                        <inertial pos="0.00363545 -1.70642e-06 0.0107468" quat="0.961434 -8.14196e-05 0.275036 7.26886e-05" mass="0.0174601" diaginertia="2.33005e-06 1.88686e-06 1.3466e-06" />
                        <joint name="joint_7" pos="0 0 0" axis="0 1 0" limited="true" range="-0.227 1.618" damping="10" frictionloss="12" />
                        <geom type="mesh" mesh="link_3.0" />
                        <geom pos="0.002 0 0.0007" type="mesh" mesh="fingertip_V2_fixed2" />
                    </body>
                </body>
            </body>
        </body>
        <body name="link_8" pos="0 -0.0435 -0.001542" quat="0.999048 0.0436194 0 0">
            <inertial pos="-0.000778127 -1.02867e-05 0.00828249" quat="0.684133 0.685936 -0.175375 0.175209" mass="0.00868607" diaginertia="9.19262e-07 8.2734e-07 4.2643e-07" />
            <joint name="joint_8" pos="0 0 0" axis="0 0 1" limited="true" range="-0.47 0.47" damping="3" frictionloss="10" />
            <geom type="mesh" mesh="link_0.0" />
            <body name="link_9" pos="0 0 0.0164">
                <inertial pos="2.75253e-08 -9.05957e-05 0.0269998" quat="1 -3.06263e-06 1.74064e-11 5.68349e-06" mass="0.0326268" diaginertia="1.41894e-05 1.3489e-05 2.71036e-06" />
                <joint name="joint_9" pos="0 0 0" axis="0 1 0" limited="true" range="-0.196 1.61" damping="3" frictionloss="5" />
                <geom type="mesh" mesh="link_1.0" />
                <body name="link_10" pos="0 0 0.054">
                    <inertial pos="-0.000192882 -7.79043e-05 0.022586" quat="0.999903 -0.000286998 0.0139235 0.000170086" mass="0.0225751" diaginertia="5.24199e-06 4.4452e-06 2.04635e-06" />
                    <joint name="joint_10" pos="0 0 0" axis="0 1 0" limited="true" range="-0.174 1.709" damping="8" frictionloss="10" />
                    <geom type="mesh" mesh="link_2.0" />
                    <body name="link_11" pos="0 0 0.0384">
                        <inertial pos="0.00363545 -1.70642e-06 0.0107468" quat="0.961434 -8.14196e-05 0.275036 7.26886e-05" mass="0.0174601" diaginertia="2.33005e-06 1.88686e-06 1.3466e-06" />
                        <joint name="joint_11" pos="0 0 0" axis="0 1 0" limited="true" range="-0.227 1.618" damping="10" frictionloss="12" />
                        <geom type="mesh" mesh="link_3.0" />
                        <geom pos="0.002 0 0.0007" type="mesh" mesh="fingertip_V2_fixed2" />
                    </body>
                </body>
            </body>
        </body>
        <body name="link_12" pos="-0.0182 0.019333 -0.045987" quat="0.477714 -0.521334 -0.521334 -0.477714">
            <inertial pos="-0.0179151 0.00802441 0.0123141" quat="0.700903 0.0591414 -0.0631653 0.707989" mass="0.0487096" diaginertia="1.36908e-05 1.16695e-05 9.05116e-06" />
            <joint name="joint_12" pos="0 0 0" axis="-1 0 0" limited="true" range="0.263 1.396" damping="3" frictionloss="10" />
            <geom type="mesh" mesh="link_12.0_right" />
            <body name="link_13" pos="-0.027 0.005 0.0399">
                <inertial pos="-0.000782027 -1.02494e-05 0.00810454" quat="0.683918 0.68572 -0.176217 0.176045" mass="0.00867364" diaginertia="9.17605e-07 8.25876e-07 4.25231e-07" />
                <joint name="joint_13" pos="0 0 0" axis="0 0 1" limited="true" range="-0.105 1.163" damping="3" frictionloss="5" />
                <geom type="mesh" mesh="link_13.0" />
                <body name="link_14" pos="0 0 0.0177">
                    <inertial pos="-0.000164336 1.71485e-05 0.0211119" quat="0.99996 3.0356e-05 -0.00896424 0.000113178" mass="0.0289572" diaginertia="9.68949e-06 8.47399e-06 2.75595e-06" />
                    <joint name="joint_14" pos="0 0 0" axis="0 1 0" limited="true" range="-0.189 1.644" damping="3" frictionloss="10" />
                    <geom type="mesh" mesh="link_14.0" />
                    <body name="link_15" pos="0 0 0.0514">
                        <inertial pos="0.00249038 2.54029e-06 0.0183343" quat="0.992746 0.000427745 0.120201 -0.00277008" mass="0.0273663" diaginertia="6.17941e-06 5.94892e-06 2.13101e-06" />
                        <joint name="joint_15" pos="0 0 0" axis="0 1 0" limited="true" range="-0.162 1.719" damping="3" frictionloss="12" />
                        <geom type="mesh" mesh="link_15.0" />
                        <geom pos="0.002 0 0.0163" type="mesh" mesh="fingertip_V2_fixed2" />
                    </body>
                </body>
            </body>
        </body>
    </worldbody>
</mujoco>
